Workbook

Sheet DS
A1: dung | B1: diem | C1: fix | D1: muc | E1: trangthai
A2: Đúng như mô tả | B2: 1 | C2: Chưa sửa | D2: Nhẹ — vẫn dùng được | E2: Mới ghi nhận
A3: Gần đúng, khác một chút | B3: 2 | C3: Đã sửa | D3: Vừa — khó chịu | E3: Đang sửa
A4: Khác hẳn mô tả | B4: 3 | C4: Không cần sửa | D4: Nặng — không làm được việc | E4: Đã sửa — chờ kiểm lại
A5: Không làm được / bị kẹt | B5: 4 | C5: Để sau | E5: Đã kiểm lại — xong
A6: Chưa thử | B6: 5 | E6: Không sửa (có lý do)

Sheet ĐỌC TRƯỚC
A1: PHIẾU TRẢI NGHIỆM — Viet Anh Class
A2: Cảm ơn bạn đã dành thời gian. Phiếu này dùng lại được cho nhiều vòng thử.
A4: VIỆC CỦA BẠN
A5: Bạn làm gì | B5: Bạn đóng vai người dùng thật của app, đi theo từng chặng trong sheet mang tên bạn, rồi ghi lại app có đúng như mô tả không và bạn cảm thấy thế nào.
A6: Mất bao lâu | B6: Khoảng 60–90 phút cho vòng đầu. Các vòng sau nhanh hơn nhiều vì bạn đã quen.
A7: Địa chỉ app | B7: https://class.vietanh.org
A8: Mật khẩu | B8: Bạn KHÔNG cần mật khẩu. Ở trang đăng nhập, kéo xuống khối “Demo” và bấm đúng nút mang tên bạn.
A9: Quan trọng nhất | B9: Cột GHI CHÚ mới là thứ chúng tôi cần. Các ô chọn nhanh chỉ để thống kê. Đừng ngại viết dài, viết thẳng, chê thoải mái.
A11: CÁCH ĐIỀN — VÀ CÁCH DÙNG LẠI CHO NHIỀU VÒNG
A12: Ô tô vàng nhạt | B12: Là ô bạn cần điền. Ô trắng là phần mô tả sẵn, bạn không phải sửa.
A13: Cột “Đúng như mô tả?” | B13: Chọn từ danh sách sổ xuống. Nếu app khác mô tả, hãy nói rõ khác chỗ nào ở cột ghi chú.
A14: Cột “Dễ dùng” | B14: 1 = rất khó dùng · 5 = rất dễ. Chấm theo cảm giác thật, không cần cân nhắc nhiều.
A15: VÒNG 1 / 2 / 3 | B15: Mỗi vòng thử có một nhóm cột riêng. Vòng 1 điền trước. Sau khi đội kỹ thuật sửa, bạn quay lại điền cột “Đã sửa?” rồi thử lại và điền vòng 2. Cứ thế cho tới khi hết lỗi.
A16: Cần hơn 3 vòng? | B16: Bôi đen nhóm cột của Vòng 3 (từ cột “Đã sửa?” tới “Ghi chú”), sao chép và dán sang phải. Sổ lỗi ở sheet SỔ LỖI thì không giới hạn số vòng.
A17: Sheet SỔ LỖI | B17: Mỗi lỗi bạn gặp ghi MỘT dòng ở đó, rồi theo dõi tới khi nó được sửa xong. Đây là chỗ theo dõi xuyên suốt mọi vòng.
A19: TÀI KHOẢN CỦA TỪNG NGƯỜI
A20: Người thử | B20: Vai — bấm nút demo tương ứng | C20: Tài khoản | D20: Gắn với ai / lớp nào
A21: N1 · Giáo viên | B21: Giáo viên chủ nhiệm | C21: test1.gvcn@truongvietanh.com | D21: Chủ nhiệm lớp 7B1 · cơ sở Việt Anh Quận 2
B22: Học sinh (tổ trưởng) | C22: test1.hs@student.truongvietanh.com | D22: Học lớp 7B1 · được giao làm tổ trưởng điểm danh
B23: Phụ huynh | C23: test1.ph@truongvietanh.com | D23: Là phụ huynh của chính học sinh ở trên
A24: N2 · Ban giám hiệu | B24: Ban giám hiệu | C24: test2.bgh@truongvietanh.com | D24: Phụ trách cơ sở Việt Anh Quận 2
B25: Học sinh (thường) | C25: test2.hs@student.truongvietanh.com | D25: Học lớp 7B1 · KHÔNG phải tổ trưởng
B26: Phụ huynh | C26: test2.ph@truongvietanh.com | D26: Là phụ huynh của chính học sinh ở trên
A27: N3 · Quản trị viên | B27: Quản trị viên | C27: test3.admin@truongvietanh.com | D27: Thấy toàn bộ hệ thống, mọi cơ sở
B28: Giáo viên chủ nhiệm | C28: test3.gvcn@truongvietanh.com | D28: Chủ nhiệm lớp 6A2 · cơ sở Việt Anh Gò Vấp
B29: Học sinh | C29: test3.hs@student.truongvietanh.com | D29: Học lớp 6A2 · cơ sở Việt Anh Gò Vấp
A31: AI LIÊN QUAN TỚI AI — dùng cho phần phối hợp
A32: CƠ SỞ VIỆT ANH QUẬN 2 → lớp 7B1 → giáo viên chủ nhiệm = Người 1
A33: trong lớp 7B1 có: học sinh của Người 1 (tổ trưởng điểm danh) + học sinh của Người 2
A34: phụ huynh của Người 1 ── là cha/mẹ của ──> học sinh Người 1
A35: phụ huynh của Người 2 ── là cha/mẹ của ──> học sinh Người 2
A36: ban giám hiệu cơ sở này = Người 2 (thấy 7B1, KHÔNG thấy lớp nào của Gò Vấp)
A38: CƠ SỞ VIỆT ANH GÒ VẤP → lớp 6A2 → giáo viên chủ nhiệm = Người 3
A39: trong lớp 6A2 có: học sinh của Người 3
A40: (cơ sở này còn lớp 6A1 của tài khoản demo cũ — không thuộc phần thử)
A42: QUẢN TRỊ VIÊN = Người 3 → thấy TẤT CẢ mọi cơ sở, mọi lớp. Là người đối chứng.
A44: KHI NÀO PHẢI DỪNG NGAY
A45: Nếu bạn nhìn thấy dữ liệu của học sinh KHÔNG thuộc phạm vi mình — con của phụ huynh khác, lớp của giáo viên khác, cơ sở khác — thì DỪNG ĐỢT THỬ, chụp màn hình, và báo ngay. Đây là lỗi nghiêm trọng nhất, quan trọng hơn mọi lỗi giao diện.

Sheet APP LÀ GÌ
A1: APP NÀY LÀ GÌ — đọc 10 phút trước khi thử
A2: Viết cho người chưa từng nghe về app hay về 4DX. Không cần biết gì về máy tính.
A4: Viet Anh Class là gì?
A5: Đây là một ứng dụng web dùng trong Trường Việt Anh, mở bằng trình duyệt trên máy tính hoặc điện thoại — không phải tải về cài đặt. Mục đích của nó gói gọn trong một câu: giúp mỗi lớp chọn ra vài mục tiêu thật sự quan trọng, rồi theo dõi xem cả lớp có đang tiến về phía đó mỗi tuần hay không.
A6: Trước khi có app, những thứ này nằm rải rác: điểm danh ghi sổ, mục tiêu lớp ghi trên bảng, thành tích học sinh nằm trong đầu giáo viên. App gom lại một chỗ để giáo viên đỡ nhớ, ban giám hiệu nhìn được toàn cảnh, và phụ huynh biết con mình đang đi tới đâu.
A7: 4DX — bốn nguyên tắc app này chạy theo
A8: 4DX là cách làm việc do FranklinCovey đưa ra, ý chính rất đơn giản: việc gấp luôn lấn át việc quan trọng, nên phải cố ý chọn ra một số ít mục tiêu và bảo vệ chúng. App dịch bốn nguyên tắc đó thành bốn thứ bạn sẽ thấy trên màn hình:
A9: • MỤC TIÊU (trong app gọi là WIG) — điều quan trọng nhất lớp muốn đạt. Có ba tầng lồng nhau: mục tiêu NĂM, chia nhỏ thành mục tiêu THÁNG, rồi thành mục tiêu TUẦN. Mỗi mục tiêu phát biểu theo dạng "Từ đâu → lên đâu", ví dụ: từ 10 buổi đọc sách lên 30 buổi.
A10: • VIỆC CẦN LÀM (trong app gọi là lead measure) — hành động cụ thể lặp đi lặp lại để đạt mục tiêu. Mục tiêu là thứ bạn muốn; việc cần làm là thứ bạn kiểm soát được. Ví dụ mục tiêu "tăng buổi đọc sách" thì việc cần làm là "mỗi tối đọc 20 phút".
A11: • BẢNG ĐIỂM — chỗ nhìn một cái là biết đang thắng hay thua. Trong app là các thanh tiến độ và bảng thi đua giữa các lớp.
A12: • HỌP HÀNG TUẦN — mỗi tuần cả lớp ngồi lại xem tuần qua làm được gì và cam kết tuần tới làm gì. App có mục riêng để ghi biên bản buổi họp này.
A13: Dòng chảy của app — ai làm gì, theo thứ tự
A14: Bước | B14: Chuyện gì xảy ra
A15: 1. Quản trị viên dựng nền | B15: Tạo cơ sở (chi nhánh trường), khai cấp học, tạo lớp, mời người dùng và gán vai trò.
A16: 2. Giáo viên đặt mục tiêu | B16: Giáo viên chủ nhiệm mở mục WIG, đặt mục tiêu năm cho lớp, chia thành mục tiêu tuần, và liệt kê việc cần làm.
A17: 3. Học sinh làm và tick | B17: Mỗi em mở app, thấy việc của mình trong tuần, làm xong thì tick. Tick xong tiến độ lớp nhích lên.
A18: 4. Điểm danh mỗi ngày | B18: Giáo viên (hoặc một em được giao làm tổ trưởng) đánh dấu ai có mặt, vắng, trễ, có phép.
A19: 5. Họp WIG cuối tuần | B19: Cả lớp nhìn lại bảng điểm, ghi biên bản, chốt cam kết cho tuần sau.
A20: 6. Ban giám hiệu theo dõi | B20: Nhìn bảng tổng hợp của cả cơ sở: lớp nào đang tốt, lớp nào đang đuối.
A21: 7. Phụ huynh xem báo cáo | B21: Nhận báo cáo về riêng con mình: đi học đều không, mục tiêu tới đâu.
A22: Năm vai người dùng — nói cho dễ hiểu
A23: Vai | B23: Là ai, thấy gì, làm gì
A24: Quản trị viên | B24: Người phụ trách hệ thống của cả trường. Thấy TẤT CẢ mọi cơ sở, mọi lớp. Là người tạo cơ sở, tạo lớp, mời người mới và quyết định ai làm vai gì. Nếu có gì hỏng, đây là người sửa được.
A25: Ban giám hiệu | B25: Hiệu trưởng hoặc phó hiệu trưởng của MỘT cơ sở. Nhìn được toàn bộ các lớp trong cơ sở mình — lớp nào điểm thi đua cao, lớp nào hôm nay chưa điểm danh. Quản lý được giáo viên, khối và lớp của cơ sở mình. KHÔNG thấy được gì của cơ sở khác.
A26: Giáo viên chủ nhiệm | B26: Người dùng app nhiều nhất. Phụ trách ĐÚNG MỘT LỚP: điểm danh hằng ngày, đặt mục tiêu cho lớp, liệt kê việc cần làm, chạy buổi họp WIG hằng tuần. Không thấy được lớp của giáo viên khác.
A27: Học sinh | B27: Mở app trên điện thoại, thấy mục tiêu và việc cần làm của RIÊNG MÌNH, làm xong thì tick. Không thấy được điểm hay tiến độ cá nhân của bạn cùng lớp. Một em trong lớp có thể được giáo viên giao thêm việc điểm danh hộ — gọi là tổ trưởng điểm danh, nhưng chỉ được ghi điểm danh của ngày hôm nay.
A28: Phụ huynh | B28: Chỉ xem, không sửa gì. Thấy đúng một trang báo cáo về CON MÌNH: đi học đều không, mục tiêu tới đâu. Không thấy bất kỳ học sinh nào khác, kể cả bạn cùng lớp của con.
A29: Các mục trên thanh menu nghĩa là gì
A30: Thanh menu nằm trên cùng, màu xanh đậm. Mỗi vai thấy một số mục khác nhau — bạn sẽ KHÔNG thấy hết các mục dưới đây cùng lúc, đó là bình thường.
A31: Tên mục | B31: Mở ra cái gì
A32: Bảng điểm | B32: Trang chính của lớp: tình hình chung của lớp bạn đang phụ trách.
A33: Bảng điểm của tôi | B33: Bản dành cho học sinh: thành tích của riêng em đó (tiêu đề “Bảng thành tích của em”).
A34: Danh sách | B34: Danh sách học sinh trong lớp. Giáo viên ghi danh, cho rời lớp, chọn tổ trưởng điểm danh ở đây.
A35: Điểm danh | B35: Đánh dấu ai có mặt / vắng / trễ / có phép trong ngày, rồi bấm lưu.
A36: WIG | B36: Nơi đặt mục tiêu năm / tháng / tuần và liệt kê việc cần làm (tiêu đề “WIG & Lead measure”).
A37: Thi đua | B37: Bảng điểm thi đua — điểm cộng từ tiến độ việc cần làm, chia theo 4 lĩnh vực: Kiến thức, Kỹ năng, Tiếng Anh, Thể chất.
A38: Thời khoá biểu | B38: Lưới tiết học trong tuần. Có thể ghi thêm ngoại lệ: hôm nay huỷ tiết, dời tiết, hoặc có người dạy thay.
A39: Họp WIG | B39: Ghi biên bản buổi họp hằng tuần của lớp.
A40: Cơ sở | B40: Dành cho ban giám hiệu: bảng tổng hợp mọi lớp trong cơ sở (tiêu đề “Báo cáo cơ sở”).
A41: Quản trị | B41: Dành cho quản trị viên: người dùng, cơ sở, khối, lớp.
...

Sheet N1 · Giáo viên
A1: N1 · Giáo viên — vai chính: Giáo viên chủ nhiệm
A2: Bạn đóng vai giáo viên chủ nhiệm lớp 7B1 (cơ sở Việt Anh Quận 2). Đây là vai dùng app nhiều nhất, nên phần này dài nhất. Sau đó bạn đổi sang vai học sinh và phụ huynh để nhìn app từ phía các em và gia đình.
A4: ▸ | B4: Giáo viên chủ nhiệm | C4: test1.gvcn@truongvietanh.com | D4: Chủ nhiệm lớp 7B1 · cơ sở Việt Anh Quận 2
A5: ▸ | B5: Học sinh (tổ trưởng) | C5: test1.hs@student.truongvietanh.com | D5: Học lớp 7B1 · được giao làm tổ trưởng điểm danh
A6: ▸ | B6: Phụ huynh | C6: test1.ph@truongvietanh.com | D6: Là phụ huynh của chính học sinh ở trên
D8: VÒNG THỬ 1 | G8: GIỮA VÒNG | H8: VÒNG THỬ 2 | K8: GIỮA VÒNG | L8: VÒNG THỬ 3
A9: # | B9: BẠN LÀM GÌ | C9: BẠN SẼ THẤY GÌ | D9: Đúng như mô tả? | E9: Dễ dùng 1–5 | F9: GHI CHÚ — viết thoải mái | G9: Đã sửa? | H9: Đúng như mô tả? | I9: Dễ dùng 1–5 | J9: GHI CHÚ — viết thoải mái | K9: Đã sửa? | L9: Đúng như mô tả? | M9: Dễ dùng 1–5 | N9: GHI CHÚ — viết thoải mái | O9: ⚠
A10: ◆ VAI: GIÁO VIÊN CHỦ NHIỆM lớp 7B1 — Nút demo: “N1 · Giáo viên chủ nhiệm 7B1” — Đây là vai chính của bạn. Hãy đi chậm và ghi lại mọi chỗ thấy khó hiểu.
A11: 1 | B11: Mở https://class.vietanh.org trên máy tính. | C11: Trang đăng nhập: nền có đám đông học sinh mặc đồng phục đi lại, giữa trang là dòng chữ lớn “Viet Anh Class”, bên dưới có nút trắng “Đăng nhập với Google” và một dòng chữ nhỏ “Dành cho phụ huynh”. | O11: =IF(OR(D11="Khác hẳn mô tả",D11="Không làm được / bị kẹt",H11="Khác hẳn mô tả",H11="Không làm được / bị kẹt",L11="Khác hẳn mô tả",L11="Không làm được / bị kẹt"),"⚠","")
A12: 2 | B12: Kéo xuống dưới thẻ đăng nhập, tìm khối chữ “Demo”. Bấm nút “N1 · Giáo viên chủ nhiệm 7B1”. | C12: App vào thẳng, không hỏi mật khẩu. Hiện ra thanh menu màu xanh đậm ở trên cùng. | O12: =IF(OR(D12="Khác hẳn mô tả",D12="Không làm được / bị kẹt",H12="Khác hẳn mô tả",H12="Không làm được / bị kẹt",L12="Khác hẳn mô tả",L12="Không làm được / bị kẹt"),"⚠","")
A13: 3 | B13: Đọc lần lượt các mục trên thanh menu trên cùng. | C13: Có 6 mục: Bảng điểm · Danh sách · Điểm danh · WIG · Thi đua · Thời khoá biểu. Góc phải là tên bạn kèm dòng chữ “Giáo viên chủ nhiệm”, cạnh đó có hình cái chuông. | O13: =IF(OR(D13="Khác hẳn mô tả",D13="Không làm được / bị kẹt",H13="Khác hẳn mô tả",H13="Không làm được / bị kẹt",L13="Khác hẳn mô tả",L13="Không làm được / bị kẹt"),"⚠","")
A14: 4 | B14: Nhìn màn hình đang mở sẵn (mục “Bảng điểm”). | C14: Đây là bảng điểm của lớp bạn chủ nhiệm — lớp 7B1. Nếu thấy dòng chữ “Chưa có lớp” thì nghĩa là tài khoản chưa được gắn lớp — dừng lại và báo ngay. | O14: =IF(OR(D14="Khác hẳn mô tả",D14="Không làm được / bị kẹt",H14="Khác hẳn mô tả",H14="Không làm được / bị kẹt",L14="Khác hẳn mô tả",L14="Không làm được / bị kẹt"),"⚠","")
A15: 5 | B15: Bấm “Danh sách”. Đếm xem có bao nhiêu học sinh và ghi con số vào cột ghi chú. | C15: Tiêu đề “Danh sách lớp”. Thấy danh sách học sinh của lớp 7B1 (khoảng 3 em). Một trong số đó được đánh dấu là tổ trưởng điểm danh. | O15: =IF(OR(D15="Khác hẳn mô tả",D15="Không làm được / bị kẹt",H15="Khác hẳn mô tả",H15="Không làm được / bị kẹt",L15="Khác hẳn mô tả",L15="Không làm được / bị kẹt"),"⚠","")
A16: 6 | B16: Bấm “Điểm danh”. | C16: Tiêu đề “Điểm danh”. Mỗi học sinh một dòng, mỗi dòng có 4 lựa chọn: Có mặt · Vắng · Trễ · Có phép. Phía dưới có nút “Lưu điểm danh”. | O16: =IF(OR(D16="Khác hẳn mô tả",D16="Không làm được / bị kẹt",H16="Khác hẳn mô tả",H16="Không làm được / bị kẹt",L16="Khác hẳn mô tả",L16="Không làm được / bị kẹt"),"⚠","")
A17: 7 | B17: Chọn “Vắng” cho một em bất kỳ. KHOAN bấm lưu — nhìn cái nút lưu trước đã. | C17: Nút đổi thành “Lưu điểm danh (1)” — con số trong ngoặc là số thay đổi chưa lưu. Bạn thấy có đúng vậy không? | O17: =IF(OR(D17="Khác hẳn mô tả",D17="Không làm được / bị kẹt",H17="Khác hẳn mô tả",H17="Không làm được / bị kẹt",L17="Khác hẳn mô tả",L17="Không làm được / bị kẹt"),"⚠","")
A18: 8 | B18: Bấm “Lưu điểm danh”. | C18: App lưu xong và dòng tổng kết phía trên đổi theo (dạng “Có mặt: … / …”). | O18: =IF(OR(D18="Khác hẳn mô tả",D18="Không làm được / bị kẹt",H18="Khác hẳn mô tả",H18="Không làm được / bị kẹt",L18="Khác hẳn mô tả",L18="Không làm được / bị kẹt"),"⚠","")
A19: 9 | B19: Bấm “WIG”. | C19: Tiêu đề “WIG & Lead measure”. Đây là nơi đặt mục tiêu cho lớp. | O19: =IF(OR(D19="Khác hẳn mô tả",D19="Không làm được / bị kẹt",H19="Khác hẳn mô tả",H19="Không làm được / bị kẹt",L19="Khác hẳn mô tả",L19="Không làm được / bị kẹt"),"⚠","")
A20: 10 | B20: Ở khối tạo WIG năm, điền: “Tên mục tiêu” = Tăng số buổi đọc sách ở nhà · “Lĩnh vực” = Kiến thức · “Từ (hiện tại)” = 10 · “Đến (mục tiêu)” = 30 · “Đơn vị” = buổi · chọn “Năm học”. Bấm “+ Tạo WIG năm”. | C20: Xuất hiện một khối mới. DÒNG ĐẦU của khối là đúng cái tên bạn vừa đặt. Dòng nhỏ bên dưới ghi lĩnh vực, năm học, và “Từ 10 → 30 buổi”. | O20: =IF(OR(D20="Khác hẳn mô tả",D20="Không làm được / bị kẹt",H20="Khác hẳn mô tả",H20="Không làm được / bị kẹt",L20="Khác hẳn mô tả",L20="Không làm được / bị kẹt"),"⚠","")
A21: 11 | B21: ⚠ CỐ TÌNH LÀM SAI — Thử tạo thêm một WIG năm nữa nhưng để TRỐNG ô “Tên mục tiêu”, các ô khác điền bình thường. Bấm tạo. | C21: App phải chặn lại và báo lỗi ngay cạnh ô bị thiếu, bằng tiếng Việt dễ hiểu. Quan trọng: những gì bạn đã gõ ở các ô KHÁC phải còn nguyên, không bị xoá sạch. | O21: =IF(OR(D21="Khác hẳn mô tả",D21="Không làm được / bị kẹt",H21="Khác hẳn mô tả",H21="Không làm được / bị kẹt",L21="Khác hẳn mô tả",L21="Không làm được / bị kẹt"),"⚠","")
A22: 12 | B22: ⚠ CỐ TÌNH LÀM SAI — Thử nữa: điền “Từ (hiện tại)” = 50 và “Đến (mục tiêu)” = 20 (tức là đi lùi). Bấm tạo. | C22: App phải chặn và nói rõ vì sao — đại ý mốc xuất phát phải nhỏ hơn mục tiêu. Câu báo lỗi có dễ hiểu với bạn không? | O22: =IF(OR(D22="Khác hẳn mô tả",D22="Không làm được / bị kẹt",H22="Khác hẳn mô tả",H22="Không làm được / bị kẹt",L22="Khác hẳn mô tả",L22="Không làm được / bị kẹt"),"⚠","")
... A30: 20 | B30: Bấm vào tên bạn ở góc trên bên phải, chọn “Đăng xuất”. | C30: Quay về trang đăng nhập. | O30: =IF(OR(D30="Khác hẳn mô tả",D30="Không làm được / bị kẹt",H30="Khác hẳn mô tả",H30="Không làm được / bị kẹt",L30="Khác hẳn mô tả",L30="Không làm được / bị kẹt"),"⚠","")
A31: ◆ VAI: HỌC SINH — kiêm TỔ TRƯỞNG ĐIỂM DANH lớp 7B1 — Nút demo: “N1 · Học sinh 7B1 (tổ trưởng)” — Giờ bạn nhìn app bằng mắt của một em học sinh được giao thêm việc điểm danh hộ lớp.
A32: 21 | B32: Đăng nhập bằng nút demo “N1 · Học sinh 7B1 (tổ trưởng)”. | C32: Thanh menu ngắn hơn hẳn lúc nãy. Góc phải ghi “Học sinh”. | O32: =IF(OR(D32="Khác hẳn mô tả",D32="Không làm được / bị kẹt",H32="Khác hẳn mô tả",H32="Không làm được / bị kẹt",L32="Khác hẳn mô tả",L32="Không làm được / bị kẹt"),"⚠","")
A33: 22 | B33: Đọc các mục trên thanh menu và ghi lại vào cột ghi chú. | C33: Có “Bảng điểm của tôi” và “Thời khoá biểu”. Vì em này là tổ trưởng nên có thêm mục “Điểm danh”. Bạn đếm được mấy mục? | O33: =IF(OR(D33="Khác hẳn mô tả",D33="Không làm được / bị kẹt",H33="Khác hẳn mô tả",H33="Không làm được / bị kẹt",L33="Khác hẳn mô tả",L33="Không làm được / bị kẹt"),"⚠","")
A34: 23 | B34: Mở “Bảng điểm của tôi”. | C34: Tiêu đề “Bảng thành tích của em”. Đây là điểm và tiến độ của riêng em này. | O34: =IF(OR(D34="Khác hẳn mô tả",D34="Không làm được / bị kẹt",H34="Khác hẳn mô tả",H34="Không làm được / bị kẹt",L34="Khác hẳn mô tả",L34="Không làm được / bị kẹt"),"⚠","")
A35: 24 | B35: Tìm phần tick việc hằng ngày. Tick một việc. | C35: Việc vừa tick được đánh dấu là đã làm, tiến độ nhích lên. | O35: =IF(OR(D35="Khác hẳn mô tả",D35="Không làm được / bị kẹt",H35="Khác hẳn mô tả",H35="Không làm được / bị kẹt",L35="Khác hẳn mô tả",L35="Không làm được / bị kẹt"),"⚠","")
A36: 25 | B36: Mở “Điểm danh” rồi thử điểm danh cho lớp. | C36: Em tổ trưởng ghi được điểm danh của NGÀY HÔM NAY. Thử tìm cách sửa điểm danh của một ngày trước đó — app có cho không? Ghi lại điều bạn thấy. | O36: =IF(OR(D36="Khác hẳn mô tả",D36="Không làm được / bị kẹt",H36="Khác hẳn mô tả",H36="Không làm được / bị kẹt",L36="Khác hẳn mô tả",L36="Không làm được / bị kẹt"),"⚠","")
A37: 26 | B37: Nhìn kỹ toàn bộ màn hình: bạn có thấy điểm hay tiến độ cá nhân của bạn cùng lớp ở đâu không? | C37: KHÔNG được thấy. Em học sinh chỉ thấy thành tích của chính mình. Nếu thấy tên và điểm của bạn khác — dừng lại và báo ngay. | O37: =IF(OR(D37="Khác hẳn mô tả",D37="Không làm được / bị kẹt",H37="Khác hẳn mô tả",H37="Không làm được / bị kẹt",L37="Khác hẳn mô tả",L37="Không làm được / bị kẹt"),"⚠","")
A38: ◆ VAI: PHỤ HUYNH — Nút demo: “N1 · Phụ huynh” — Cuối cùng, bạn nhìn app bằng mắt một người cha/mẹ ở nhà.
A39: 27 | B39: Đăng xuất, rồi đăng nhập bằng nút demo “N1 · Phụ huynh”. | C39: Góc phải ghi “Phụ huynh”. Thanh menu rất ngắn. | O39: =IF(OR(D39="Khác hẳn mô tả",D39="Không làm được / bị kẹt",H39="Khác hẳn mô tả",H39="Không làm được / bị kẹt",L39="Khác hẳn mô tả",L39="Không làm được / bị kẹt"),"⚠","")
A40: 28 | B40: Đếm các mục trên thanh menu. | C40: Chỉ có mục “Báo cáo” (và cái chuông). Phụ huynh không vào được bất cứ màn quản lý nào. | O40: =IF(OR(D40="Khác hẳn mô tả",D40="Không làm được / bị kẹt",H40="Khác hẳn mô tả",H40="Không làm được / bị kẹt",L40="Khác hẳn mô tả",L40="Không làm được / bị kẹt"),"⚠","")
A41: 29 | B41: Mở “Báo cáo”. | C41: Tiêu đề “Báo cáo phụ huynh”. Thấy thông tin về CON MÌNH: lớp, số buổi vắng/trễ, tiến độ mục tiêu. | O41: =IF(OR(D41="Khác hẳn mô tả",D41="Không làm được / bị kẹt",H41="Khác hẳn mô tả",H41="Không làm được / bị kẹt",L41="Khác hẳn mô tả",L41="Không làm được / bị kẹt"),"⚠","")
A42: 30 | B42: Đếm xem báo cáo nhắc tới bao nhiêu học sinh. Ghi con số vào ghi chú. | C42: Phải đúng 1 — chỉ con của bạn. Lớp 7B1 còn có con của Người thử 2, bạn TUYỆT ĐỐI không được thấy em đó. | O42: =IF(OR(D42="Khác hẳn mô tả",D42="Không làm được / bị kẹt",H42="Khác hẳn mô tả",H42="Không làm được / bị kẹt",L42="Khác hẳn mô tả",L42="Không làm được / bị kẹt"),"⚠","")
A43: 31 | B43: Đọc báo cáo như một phụ huynh thật: bạn có hiểu con mình đang học thế nào không? | C43: Hãy viết cảm nhận thật vào ghi chú — chỗ nào khó hiểu, thiếu thông tin gì, muốn thấy thêm gì. | O43: =IF(OR(D43="Khác hẳn mô tả",D43="Không làm được / bị kẹt",H43="Khác hẳn mô tả",H43="Không làm được / bị kẹt",L43="Khác hẳn mô tả",L43="Không làm được / bị kẹt"),"⚠","")
A45: NHẬT KÝ TỰ DO — ghi bất cứ điều gì xảy ra ngoài các chặng ở trên
A46: Vòng | B46: Màn hình nào | C46: Chuyện gì xảy ra | E46: Nặng hay nhẹ | F46: Bạn mong nó phải thế nào
A60: CÂU HỎI CUỐI — trả lời sau khi đã thử hết
A61: 1. Sau khi dùng thử, bạn mô tả app này cho một đồng nghiệp chưa biết gì bằng 2–3 câu như thế nào?
A62: 2. Với vai GIÁO VIÊN CHỦ NHIỆM: việc nào bạn làm hằng ngày mà app đang bắt bấm quá nhiều bước?
A63: 3. Với vai GIÁO VIÊN CHỦ NHIỆM: phần đặt mục tiêu (WIG) có khớp với cách bạn thật sự nghĩ về mục tiêu lớp không? Chỗ nào lệch?
...

Sheet N2 · Ban giám hiệu
A1: N2 · Ban giám hiệu — vai chính: Ban giám hiệu
A2: Bạn đóng vai ban giám hiệu phụ trách cơ sở Việt Anh Quận 2. Vai này nhìn app ở tầm toàn cơ sở chứ không phải một lớp. Sau đó bạn đổi sang vai học sinh thường (không phải tổ trưởng) và phụ huynh.
A4: ▸ | B4: Ban giám hiệu | C4: test2.bgh@truongvietanh.com | D4: Phụ trách cơ sở Việt Anh Quận 2
A5: ▸ | B5: Học sinh (thường) | C5: test2.hs@student.truongvietanh.com | D5: Học lớp 7B1 · KHÔNG phải tổ trưởng
A6: ▸ | B6: Phụ huynh | C6: test2.ph@truongvietanh.com | D6: Là phụ huynh của chính học sinh ở trên
D8: VÒNG THỬ 1 | G8: GIỮA VÒNG | H8: VÒNG THỬ 2 | K8: GIỮA VÒNG | L8: VÒNG THỬ 3
A9: # | B9: BẠN LÀM GÌ | C9: BẠN SẼ THẤY GÌ | D9: Đúng như mô tả? | E9: Dễ dùng 1–5 | F9: GHI CHÚ — viết thoải mái | G9: Đã sửa? | H9: Đúng như mô tả? | I9: Dễ dùng 1–5 | J9: GHI CHÚ — viết thoải mái | K9: Đã sửa? | L9: Đúng như mô tả? | M9: Dễ dùng 1–5 | N9: GHI CHÚ — viết thoải mái | O9: ⚠
A10: ◆ VAI: BAN GIÁM HIỆU — cơ sở Việt Anh Quận 2 — Nút demo: “N2 · Ban giám hiệu Quận 2” — Vai chính của bạn. Bạn nhìn app ở tầm cả cơ sở, không phải một lớp.
A11: 1 | B11: Mở https://class.vietanh.org, bấm nút demo “N2 · Ban giám hiệu Quận 2”. | C11: Vào thẳng. Góc phải ghi “Ban giám hiệu”. | O11: =IF(OR(D11="Khác hẳn mô tả",D11="Không làm được / bị kẹt",H11="Khác hẳn mô tả",H11="Không làm được / bị kẹt",L11="Khác hẳn mô tả",L11="Không làm được / bị kẹt"),"⚠","")
A12: 2 | B12: Đọc các mục trên thanh menu và ghi lại. | C12: Có 3 mục: Cơ sở · Danh sách · Thời khoá biểu. Ít hơn giáo viên. Bạn thấy như vậy có hợp lý với công việc của ban giám hiệu không? | O12: =IF(OR(D12="Khác hẳn mô tả",D12="Không làm được / bị kẹt",H12="Khác hẳn mô tả",H12="Không làm được / bị kẹt",L12="Khác hẳn mô tả",L12="Không làm được / bị kẹt"),"⚠","")
A13: 3 | B13: Mở “Cơ sở”. | C13: Tiêu đề “Báo cáo cơ sở”. Một bảng gom theo khối: dòng khối in đậm, dưới đó là các lớp, cuối bảng là dòng “Toàn trường”. Các cột: Lớp · Sĩ số · Điểm thi đua · Điểm danh hôm nay. | O13: =IF(OR(D13="Khác hẳn mô tả",D13="Không làm được / bị kẹt",H13="Khác hẳn mô tả",H13="Không làm được / bị kẹt",L13="Khác hẳn mô tả",L13="Không làm được / bị kẹt"),"⚠","")
A14: 4 | B14: ĐẾM xem bảng liệt kê bao nhiêu lớp. Ghi con số và TÊN từng lớp vào ghi chú. | C14: Phải chỉ thấy lớp của cơ sở Quận 2 (lớp 7B1). Nếu thấy 6A1 hoặc 6A2 — đó là lớp cơ sở Gò Vấp, bạn KHÔNG được thấy. Thấy là dừng đợt thử và báo ngay. | O14: =IF(OR(D14="Khác hẳn mô tả",D14="Không làm được / bị kẹt",H14="Khác hẳn mô tả",H14="Không làm được / bị kẹt",L14="Khác hẳn mô tả",L14="Không làm được / bị kẹt"),"⚠","")
A15: 5 | B15: Nhìn dòng “Toàn trường” cuối bảng. | C15: Cột sĩ số là tổng số học sinh các lớp bạn quản. Cột điểm là điểm trung bình các lớp, không phải tổng. | O15: =IF(OR(D15="Khác hẳn mô tả",D15="Không làm được / bị kẹt",H15="Khác hẳn mô tả",H15="Không làm được / bị kẹt",L15="Khác hẳn mô tả",L15="Không làm được / bị kẹt"),"⚠","")
A16: 6 | B16: Kéo xuống phần “Quản lý giáo viên”. | C16: Có ô điền email và nút “Mời giáo viên”. Bên dưới là danh sách giáo viên trong cơ sở bạn, mỗi người có nút “Vô hiệu”. | O16: =IF(OR(D16="Khác hẳn mô tả",D16="Không làm được / bị kẹt",H16="Khác hẳn mô tả",H16="Không làm được / bị kẹt",L16="Khác hẳn mô tả",L16="Không làm được / bị kẹt"),"⚠","")
A17: 7 | B17: ⚠ CỐ TÌNH LÀM SAI — Gõ một chuỗi không phải email (ví dụ: abcxyz) vào ô mời giáo viên rồi bấm “Mời giáo viên”. | C17: App phải chặn và nói rõ email không hợp lệ, không được im lặng hay báo thành công giả. | O17: =IF(OR(D17="Khác hẳn mô tả",D17="Không làm được / bị kẹt",H17="Khác hẳn mô tả",H17="Không làm được / bị kẹt",L17="Khác hẳn mô tả",L17="Không làm được / bị kẹt"),"⚠","")
A18: 8 | B18: Mời thử một email hợp lệ, ví dụ giaovien.moi@truongvietanh.com. | C18: Xuất hiện khối “Lời mời chưa dùng” với email vừa mời, kèm nút huỷ. App có nói cho bạn biết chuyện gì xảy ra tiếp theo không? | O18: =IF(OR(D18="Khác hẳn mô tả",D18="Không làm được / bị kẹt",H18="Khác hẳn mô tả",H18="Không làm được / bị kẹt",L18="Khác hẳn mô tả",L18="Không làm được / bị kẹt"),"⚠","")
A19: 9 | B19: Bấm huỷ lời mời vừa tạo. | C19: Email đó biến khỏi danh sách lời mời. | O19: =IF(OR(D19="Khác hẳn mô tả",D19="Không làm được / bị kẹt",H19="Khác hẳn mô tả",H19="Không làm được / bị kẹt",L19="Khác hẳn mô tả",L19="Không làm được / bị kẹt"),"⚠","")
A20: 10 | B20: Kéo xuống phần “Quản lý Khối”. | C20: Có ô chọn “Cấp học” và nút lưu, bên dưới là danh sách khối. Nếu cơ sở đã khai cấp học thì các khối hiện ra sẵn (Khối 6, 7, 8, 9) và KHÔNG có ô gõ tên khối bằng tay. | O20: =IF(OR(D20="Khác hẳn mô tả",D20="Không làm được / bị kẹt",H20="Khác hẳn mô tả",H20="Không làm được / bị kẹt",L20="Khác hẳn mô tả",L20="Không làm được / bị kẹt"),"⚠","")
A21: 11 | B21: Kéo xuống phần “Tạo lớp”. Thử tạo một lớp mới tên 7B2. | C21: Form có các ô: tên lớp, năm học, cơ sở, khối, giáo viên chủ nhiệm. Lớp mới xuất hiện trong bảng ở trên. | O21: =IF(OR(D21="Khác hẳn mô tả",D21="Không làm được / bị kẹt",H21="Khác hẳn mô tả",H21="Không làm được / bị kẹt",L21="Khác hẳn mô tả",L21="Không làm được / bị kẹt"),"⚠","")
A22: 12 | B22: Mở “Danh sách”. | C22: Tiêu đề “Danh sách lớp”. Bạn xem được danh sách học sinh, nhưng thử tìm xem có nút ghi danh hay xoá học sinh không — ban giám hiệu chỉ nên XEM. Ghi lại điều bạn thấy. | O22: =IF(OR(D22="Khác hẳn mô tả",D22="Không làm được / bị kẹt",H22="Khác hẳn mô tả",H22="Không làm được / bị kẹt",L22="Khác hẳn mô tả",L22="Không làm được / bị kẹt"),"⚠","")
... A25: 15 | B25: 📱 TRÊN ĐIỆN THOẠI — Mở lại “Cơ sở” trên điện thoại. | C25: Bảng có nhiều cột nên chắc phải kéo ngang — kéo có mượt không, có đọc được không? Ghi cảm nhận. | O25: =IF(OR(D25="Khác hẳn mô tả",D25="Không làm được / bị kẹt",H25="Khác hẳn mô tả",H25="Không làm được / bị kẹt",L25="Khác hẳn mô tả",L25="Không làm được / bị kẹt"),"⚠","")
A26: ◆ VAI: HỌC SINH THƯỜNG lớp 7B1 — Nút demo: “N2 · Học sinh 7B1” — Em này học CÙNG LỚP với học sinh của Người thử 1, nhưng KHÔNG phải tổ trưởng.
A27: 16 | B27: Đăng xuất, đăng nhập bằng nút demo “N2 · Học sinh 7B1”. | C27: Góc phải ghi “Học sinh”. | O27: =IF(OR(D27="Khác hẳn mô tả",D27="Không làm được / bị kẹt",H27="Khác hẳn mô tả",H27="Không làm được / bị kẹt",L27="Khác hẳn mô tả",L27="Không làm được / bị kẹt"),"⚠","")
A28: 17 | B28: Đếm các mục trên thanh menu, ghi lại. | C28: Chỉ có “Bảng điểm của tôi” và “Thời khoá biểu”. KHÔNG có mục “Điểm danh” — vì em này không phải tổ trưởng. Nếu thấy mục Điểm danh, báo ngay. | O28: =IF(OR(D28="Khác hẳn mô tả",D28="Không làm được / bị kẹt",H28="Khác hẳn mô tả",H28="Không làm được / bị kẹt",L28="Khác hẳn mô tả",L28="Không làm được / bị kẹt"),"⚠","")
A29: 18 | B29: Mở “Bảng điểm của tôi”. | C29: Tiêu đề “Bảng thành tích của em”. Chỉ thành tích của riêng em này. | O29: =IF(OR(D29="Khác hẳn mô tả",D29="Không làm được / bị kẹt",H29="Khác hẳn mô tả",H29="Không làm được / bị kẹt",L29="Khác hẳn mô tả",L29="Không làm được / bị kẹt"),"⚠","")
A30: 19 | B30: Tìm và tick một việc trong phần việc hằng ngày. | C30: Tick được, tiến độ đổi. Thử tick cho một ngày của tuần trước xem app có cho không, ghi lại. | O30: =IF(OR(D30="Khác hẳn mô tả",D30="Không làm được / bị kẹt",H30="Khác hẳn mô tả",H30="Không làm được / bị kẹt",L30="Khác hẳn mô tả",L30="Không làm được / bị kẹt"),"⚠","")
A31: 20 | B31: Nhìn kỹ: có thấy tên hoặc điểm của bạn cùng lớp ở đâu không? | C31: KHÔNG được thấy. Thấy là báo ngay. | O31: =IF(OR(D31="Khác hẳn mô tả",D31="Không làm được / bị kẹt",H31="Khác hẳn mô tả",H31="Không làm được / bị kẹt",L31="Khác hẳn mô tả",L31="Không làm được / bị kẹt"),"⚠","")
A32: ◆ VAI: PHỤ HUYNH — Nút demo: “N2 · Phụ huynh” — Bạn là phụ huynh của em học sinh vừa rồi.
A33: 21 | B33: Đăng xuất, đăng nhập bằng nút demo “N2 · Phụ huynh”. | C33: Góc phải ghi “Phụ huynh”, thanh menu chỉ còn mục “Báo cáo”. | O33: =IF(OR(D33="Khác hẳn mô tả",D33="Không làm được / bị kẹt",H33="Khác hẳn mô tả",H33="Không làm được / bị kẹt",L33="Khác hẳn mô tả",L33="Không làm được / bị kẹt"),"⚠","")
A34: 22 | B34: Mở “Báo cáo”. ĐẾM xem có bao nhiêu học sinh được nhắc tới. | C34: Phải đúng 1 — con bạn. Con của Người thử 1 học CÙNG LỚP 7B1 nhưng bạn TUYỆT ĐỐI không được thấy. Thấy là dừng đợt thử và báo ngay. | O34: =IF(OR(D34="Khác hẳn mô tả",D34="Không làm được / bị kẹt",H34="Khác hẳn mô tả",H34="Không làm được / bị kẹt",L34="Khác hẳn mô tả",L34="Không làm được / bị kẹt"),"⚠","")
A35: 23 | B35: Đọc kỹ báo cáo: nó cho bạn biết những gì về con? | C35: Ghi lại: thông tin nào hữu ích, thông tin nào thừa, còn thiếu thứ gì bạn muốn biết. | O35: =IF(OR(D35="Khác hẳn mô tả",D35="Không làm được / bị kẹt",H35="Khác hẳn mô tả",H35="Không làm được / bị kẹt",L35="Khác hẳn mô tả",L35="Không làm được / bị kẹt"),"⚠","")
A36: 24 | B36: ⚠ CỐ TÌNH LÀM SAI — Thử gõ thẳng vào thanh địa chỉ: class.vietanh.org/roster rồi Enter. | C36: App phải đẩy bạn đi chỗ khác hoặc báo không có quyền. Nếu mở được danh sách lớp — dừng đợt thử và báo ngay. | O36: =IF(OR(D36="Khác hẳn mô tả",D36="Không làm được / bị kẹt",H36="Khác hẳn mô tả",H36="Không làm được / bị kẹt",L36="Khác hẳn mô tả",L36="Không làm được / bị kẹt"),"⚠","")
A37: 25 | B37: 📱 TRÊN ĐIỆN THOẠI — Mở báo cáo trên điện thoại như một phụ huynh thật. | C37: Đọc được thoải mái không? Đây là màn phụ huynh dùng nhiều nhất nên hãy ghi kỹ cảm nhận. | O37: =IF(OR(D37="Khác hẳn mô tả",D37="Không làm được / bị kẹt",H37="Khác hẳn mô tả",H37="Không làm được / bị kẹt",L37="Khác hẳn mô tả",L37="Không làm được / bị kẹt"),"⚠","")
A39: NHẬT KÝ TỰ DO — ghi bất cứ điều gì xảy ra ngoài các chặng ở trên
A40: Vòng | B40: Màn hình nào | C40: Chuyện gì xảy ra | E40: Nặng hay nhẹ | F40: Bạn mong nó phải thế nào
A54: CÂU HỎI CUỐI — trả lời sau khi đã thử hết
A55: 1. Sau khi dùng thử, bạn mô tả app này cho một đồng nghiệp chưa biết gì bằng 2–3 câu như thế nào?
A56: 2. Với vai BAN GIÁM HIỆU: mở app buổi sáng, bạn muốn thấy NGAY con số gì? App có cho bạn thấy nó không?
A57: 3. Với vai BAN GIÁM HIỆU: menu chỉ có 3 mục (Cơ sở · Danh sách · Thời khoá biểu). Thiếu gì bạn thật sự cần?
A58: 4. Với vai BAN GIÁM HIỆU: bạn có muốn tự mời và quản lý giáo viên không, hay việc đó nên để quản trị viên làm?
...

Sheet N3 · Quản trị viên
A1: N3 · Quản trị viên — vai chính: Quản trị viên
A2: Bạn đóng vai quản trị viên — người thấy được toàn hệ thống và tạo lập mọi thứ. Bạn cũng là người đối chứng: khi hai bạn kia thao tác, bạn kiểm xem hệ thống có ghi đúng không. Sau đó bạn đổi sang vai giáo viên chủ nhiệm một lớp ở cơ sở KHÁC, và vai học sinh lớp đó.
A4: ▸ | B4: Quản trị viên | C4: test3.admin@truongvietanh.com | D4: Thấy toàn bộ hệ thống, mọi cơ sở
A5: ▸ | B5: Giáo viên chủ nhiệm | C5: test3.gvcn@truongvietanh.com | D5: Chủ nhiệm lớp 6A2 · cơ sở Việt Anh Gò Vấp
A6: ▸ | B6: Học sinh | C6: test3.hs@student.truongvietanh.com | D6: Học lớp 6A2 · cơ sở Việt Anh Gò Vấp
D8: VÒNG THỬ 1 | G8: GIỮA VÒNG | H8: VÒNG THỬ 2 | K8: GIỮA VÒNG | L8: VÒNG THỬ 3
A9: # | B9: BẠN LÀM GÌ | C9: BẠN SẼ THẤY GÌ | D9: Đúng như mô tả? | E9: Dễ dùng 1–5 | F9: GHI CHÚ — viết thoải mái | G9: Đã sửa? | H9: Đúng như mô tả? | I9: Dễ dùng 1–5 | J9: GHI CHÚ — viết thoải mái | K9: Đã sửa? | L9: Đúng như mô tả? | M9: Dễ dùng 1–5 | N9: GHI CHÚ — viết thoải mái | O9: ⚠
A10: ◆ VAI: QUẢN TRỊ VIÊN — Nút demo: “N3 · Quản trị viên” — Vai chính của bạn — người thấy toàn hệ thống. Bạn cũng là người đối chứng cho hai bạn kia.
A11: 1 | B11: Mở https://class.vietanh.org, bấm nút demo “N3 · Quản trị viên”. | C11: Vào thẳng. Góc phải ghi “Quản trị viên”. | O11: =IF(OR(D11="Khác hẳn mô tả",D11="Không làm được / bị kẹt",H11="Khác hẳn mô tả",H11="Không làm được / bị kẹt",L11="Khác hẳn mô tả",L11="Không làm được / bị kẹt"),"⚠","")
A12: 2 | B12: Đọc các mục trên thanh menu, ghi lại. | C12: Nhiều mục nhất: Quản trị · Bảng điểm · Danh sách · Điểm danh · WIG · Thi đua · Thời khoá biểu. | O12: =IF(OR(D12="Khác hẳn mô tả",D12="Không làm được / bị kẹt",H12="Khác hẳn mô tả",H12="Không làm được / bị kẹt",L12="Khác hẳn mô tả",L12="Không làm được / bị kẹt"),"⚠","")
A13: 3 | B13: Mở “Quản trị”. | C13: Màn quản trị có hai phần lớn: “Người dùng” và “Lớp & Cơ sở”. | O13: =IF(OR(D13="Khác hẳn mô tả",D13="Không làm được / bị kẹt",H13="Khác hẳn mô tả",H13="Không làm được / bị kẹt",L13="Khác hẳn mô tả",L13="Không làm được / bị kẹt"),"⚠","")
A14: 4 | B14: Ở phần “Người dùng”, gõ chữ test vào ô “Tìm theo tên / email”. | C14: Hiện ra 9 tài khoản thử của cả ba người. Mỗi dòng có ô đổi vai trò. | O14: =IF(OR(D14="Khác hẳn mô tả",D14="Không làm được / bị kẹt",H14="Khác hẳn mô tả",H14="Không làm được / bị kẹt",L14="Khác hẳn mô tả",L14="Không làm được / bị kẹt"),"⚠","")
A15: 5 | B15: ĐẾM xem có bao nhiêu tài khoản đang ở vai “Chờ cấp quyền”. Ghi con số. | C15: Nên là 0. Nếu có tài khoản nào còn “Chờ cấp quyền” thì người đó sẽ không đăng nhập dùng được — báo lại ngay. | O15: =IF(OR(D15="Khác hẳn mô tả",D15="Không làm được / bị kẹt",H15="Khác hẳn mô tả",H15="Không làm được / bị kẹt",L15="Khác hẳn mô tả",L15="Không làm được / bị kẹt"),"⚠","")
A16: 6 | B16: Mở phần “Lớp & Cơ sở”. Đếm số cơ sở và số lớp, ghi lại. | C16: Thấy cả hai cơ sở (Việt Anh Gò Vấp, Việt Anh Quận 2) và tất cả các lớp — quản trị viên thấy hết, khác hẳn ban giám hiệu. | O16: =IF(OR(D16="Khác hẳn mô tả",D16="Không làm được / bị kẹt",H16="Khác hẳn mô tả",H16="Không làm được / bị kẹt",L16="Khác hẳn mô tả",L16="Không làm được / bị kẹt"),"⚠","")
A17: 7 | B17: Trong một thẻ cơ sở, tìm phần “Khối”. | C17: Nếu cơ sở đã khai cấp học thì các khối đã có sẵn theo chuẩn và không cho gõ tay. Bạn thấy vậy có hợp lý không? | O17: =IF(OR(D17="Khác hẳn mô tả",D17="Không làm được / bị kẹt",H17="Khác hẳn mô tả",H17="Không làm được / bị kẹt",L17="Khác hẳn mô tả",L17="Không làm được / bị kẹt"),"⚠","")
A18: 8 | B18: Thử phần “Tạo cơ sở”: điền tên, mã, chọn “Cấp học”. | C18: Sau khi chọn cấp học, app cho bạn biết trước sẽ tạo ra những khối nào. Có đúng không? | O18: =IF(OR(D18="Khác hẳn mô tả",D18="Không làm được / bị kẹt",H18="Khác hẳn mô tả",H18="Không làm được / bị kẹt",L18="Khác hẳn mô tả",L18="Không làm được / bị kẹt"),"⚠","")
A19: 9 | B19: ⚠ CỐ TÌNH LÀM SAI — Thử tạo cơ sở mà bỏ trống ô “Cấp học”. | C19: App phải chặn và nói rõ cần chọn cấp học. | O19: =IF(OR(D19="Khác hẳn mô tả",D19="Không làm được / bị kẹt",H19="Khác hẳn mô tả",H19="Không làm được / bị kẹt",L19="Khác hẳn mô tả",L19="Không làm được / bị kẹt"),"⚠","")
A20: 10 | B20: Tìm phần “Mời người dùng mới”. Mời thử một email, chọn vai trò. | C20: App xác nhận đã mời và nói rõ vai trò sẽ được gán khi người đó đăng nhập lần đầu. | O20: =IF(OR(D20="Khác hẳn mô tả",D20="Không làm được / bị kẹt",H20="Khác hẳn mô tả",H20="Không làm được / bị kẹt",L20="Khác hẳn mô tả",L20="Không làm được / bị kẹt"),"⚠","")
A21: 11 | B21: Tìm phần “Phân công GVCN cho lớp”. Xem cách nó hoạt động. | C21: Chọn được người và lớp. Ghi lại: cách chọn này có dễ hiểu không? | O21: =IF(OR(D21="Khác hẳn mô tả",D21="Không làm được / bị kẹt",H21="Khác hẳn mô tả",H21="Không làm được / bị kẹt",L21="Khác hẳn mô tả",L21="Không làm được / bị kẹt"),"⚠","")
A22: 12 | B22: Mở “Điểm danh”. Thử sửa điểm danh của MỘT NGÀY TRƯỚC. | C22: Quản trị viên được sửa ngày cũ. Thử xem lùi được bao xa, ghi lại. | O22: =IF(OR(D22="Khác hẳn mô tả",D22="Không làm được / bị kẹt",H22="Khác hẳn mô tả",H22="Không làm được / bị kẹt",L22="Khác hẳn mô tả",L22="Không làm được / bị kẹt"),"⚠","")
... A24: 14 | B24: 📱 TRÊN ĐIỆN THOẠI — Mở màn “Quản trị” trên điện thoại. | C24: Đây là màn nhiều thông tin nhất. Trên điện thoại có dùng nổi không? Ghi thật kỹ. | O24: =IF(OR(D24="Khác hẳn mô tả",D24="Không làm được / bị kẹt",H24="Khác hẳn mô tả",H24="Không làm được / bị kẹt",L24="Khác hẳn mô tả",L24="Không làm được / bị kẹt"),"⚠","")
A25: ◆ VAI: GIÁO VIÊN CHỦ NHIỆM lớp 6A2 — cơ sở Việt Anh Gò Vấp — Nút demo: “N3 · Giáo viên chủ nhiệm 6A2” — Lớp này ở cơ sở KHÁC với lớp của Người thử 1. Đây là vế đối chứng cho các phép thử ranh giới.
A26: 15 | B26: Đăng xuất, đăng nhập bằng nút demo “N3 · Giáo viên chủ nhiệm 6A2”. | C26: Góc phải ghi “Giáo viên chủ nhiệm”. | O26: =IF(OR(D26="Khác hẳn mô tả",D26="Không làm được / bị kẹt",H26="Khác hẳn mô tả",H26="Không làm được / bị kẹt",L26="Khác hẳn mô tả",L26="Không làm được / bị kẹt"),"⚠","")
A27: 16 | B27: Mở “Danh sách”. Ghi lại tên lớp và số học sinh. | C27: Phải là lớp 6A2. Nếu thấy lớp 7B1 hoặc 6A1 — bạn đang thấy lớp của người khác, báo ngay. | O27: =IF(OR(D27="Khác hẳn mô tả",D27="Không làm được / bị kẹt",H27="Khác hẳn mô tả",H27="Không làm được / bị kẹt",L27="Khác hẳn mô tả",L27="Không làm được / bị kẹt"),"⚠","")
A28: 17 | B28: Mở “WIG”, tạo một WIG năm cho lớp 6A2. | C28: Tạo được bình thường, giống như Người thử 1 đã làm với lớp của họ. | O28: =IF(OR(D28="Khác hẳn mô tả",D28="Không làm được / bị kẹt",H28="Khác hẳn mô tả",H28="Không làm được / bị kẹt",L28="Khác hẳn mô tả",L28="Không làm được / bị kẹt"),"⚠","")
A29: 18 | B29: Mở “Điểm danh”, điểm danh cho lớp 6A2 rồi lưu. | C29: Lưu được. Ghi lại thời gian bạn lưu để đối chiếu ở phần phối hợp. | O29: =IF(OR(D29="Khác hẳn mô tả",D29="Không làm được / bị kẹt",H29="Khác hẳn mô tả",H29="Không làm được / bị kẹt",L29="Khác hẳn mô tả",L29="Không làm được / bị kẹt"),"⚠","")
A30: 19 | B30: Thử tìm cách xem dữ liệu lớp 7B1 (lớp của Người thử 1) bằng mọi cách bạn nghĩ ra. | C30: KHÔNG được vào. Nếu tìm được đường nào vào — ghi rõ bạn đã bấm gì, và báo ngay. | O30: =IF(OR(D30="Khác hẳn mô tả",D30="Không làm được / bị kẹt",H30="Khác hẳn mô tả",H30="Không làm được / bị kẹt",L30="Khác hẳn mô tả",L30="Không làm được / bị kẹt"),"⚠","")
A31: ◆ VAI: HỌC SINH lớp 6A2 — Nút demo: “N3 · Học sinh 6A2” — Em học sinh ở cơ sở Gò Vấp.
A32: 20 | B32: Đăng xuất, đăng nhập bằng nút demo “N3 · Học sinh 6A2”. | C32: Góc phải ghi “Học sinh”. | O32: =IF(OR(D32="Khác hẳn mô tả",D32="Không làm được / bị kẹt",H32="Khác hẳn mô tả",H32="Không làm được / bị kẹt",L32="Khác hẳn mô tả",L32="Không làm được / bị kẹt"),"⚠","")
A33: 21 | B33: Mở “Bảng điểm của tôi”. | C33: Tiêu đề “Bảng thành tích của em”. Chỉ dữ liệu của em này, lớp 6A2. | O33: =IF(OR(D33="Khác hẳn mô tả",D33="Không làm được / bị kẹt",H33="Khác hẳn mô tả",H33="Không làm được / bị kẹt",L33="Khác hẳn mô tả",L33="Không làm được / bị kẹt"),"⚠","")
A34: 22 | B34: Tìm phần việc hằng ngày và tick thử. | C34: Tick được. Nếu chưa có việc nào thì hiện dòng báo chưa có — ghi lại chính xác dòng chữ đó. | O34: =IF(OR(D34="Khác hẳn mô tả",D34="Không làm được / bị kẹt",H34="Khác hẳn mô tả",H34="Không làm được / bị kẹt",L34="Khác hẳn mô tả",L34="Không làm được / bị kẹt"),"⚠","")
A35: 23 | B35: Mở “Thời khoá biểu”. | C35: Thời khoá biểu của lớp 6A2. | O35: =IF(OR(D35="Khác hẳn mô tả",D35="Không làm được / bị kẹt",H35="Khác hẳn mô tả",H35="Không làm được / bị kẹt",L35="Khác hẳn mô tả",L35="Không làm được / bị kẹt"),"⚠","")
A36: 24 | B36: ⚠ CỐ TÌNH LÀM SAI — Gõ thẳng vào thanh địa chỉ: class.vietanh.org/admin rồi Enter. | C36: App phải chặn. Nếu mở được màn quản trị — dừng đợt thử và báo ngay. | O36: =IF(OR(D36="Khác hẳn mô tả",D36="Không làm được / bị kẹt",H36="Khác hẳn mô tả",H36="Không làm được / bị kẹt",L36="Khác hẳn mô tả",L36="Không làm được / bị kẹt"),"⚠","")
A38: NHẬT KÝ TỰ DO — ghi bất cứ điều gì xảy ra ngoài các chặng ở trên
A39: Vòng | B39: Màn hình nào | C39: Chuyện gì xảy ra | E39: Nặng hay nhẹ | F39: Bạn mong nó phải thế nào
A53: CÂU HỎI CUỐI — trả lời sau khi đã thử hết
A54: 1. Sau khi dùng thử, bạn mô tả app này cho một đồng nghiệp chưa biết gì bằng 2–3 câu như thế nào?
A55: 2. Với vai QUẢN TRỊ VIÊN: dựng một cơ sở mới từ số không mất bao lâu? Bước nào rối nhất?
A56: 3. Với vai QUẢN TRỊ VIÊN: nếu một giáo viên mới vào trường ngày mai, bạn có tự tin làm được đủ các bước để họ dùng được app không?
A57: 4. Với vai QUẢN TRỊ VIÊN: chỗ nào bạn sợ bấm nhầm là hỏng dữ liệu?
...

Sheet PHỐI HỢP
A1: KỊCH BẢN PHỐI HỢP — cần cả ba người cùng mở app một lúc
A2: Hẹn nhau một khung giờ. Mỗi kịch bản làm đúng thứ tự, đọc kết quả phải thấy rồi mới sang kịch bản kế.
A4: Mã | B4: Loại | C4: Tên kịch bản | D4: NGƯỜI 1 làm gì | E4: NGƯỜI 2 làm gì | F4: NGƯỜI 3 làm gì | G4: KẾT QUẢ PHẢI THẤY | H4: Lưu ý | I4: Kết quả thực tế | J4: Ghi chú của cả nhóm
A5: KB1 | B5: RANH GIỚI DỮ LIỆU | C5: Ban giám hiệu không được thấy lớp của cơ sở khác | D5: Đăng nhập vai GIÁO VIÊN CHỦ NHIỆM 7B1. Mở “Danh sách”, ghi lại TÊN LỚP mình đang phụ trách. | E5: Đăng nhập vai BAN GIÁM HIỆU. Mở “Cơ sở”. ĐẾM số lớp trong bảng và ghi lại TÊN từng lớp. | F5: Đăng nhập vai QUẢN TRỊ VIÊN. Mở “Quản trị” → phần “Lớp & Cơ sở”. ĐẾM tổng số lớp trong toàn hệ thống. | G5: Số lớp Người 2 đếm được phải NHỎ HƠN số lớp Người 3 đếm được. Trong danh sách của Người 2 chỉ được có lớp thuộc cơ sở Việt Anh Quận 2. Hai lớp 6A1 và 6A2 (cơ sở Gò Vấp) KHÔNG được xuất hiện. | H5: Nếu Người 2 thấy bất kỳ lớp nào của cơ sở Gò Vấp — DỪNG TOÀN BỘ ĐỢT THỬ và báo ngay. Đây là lỗi rò rỉ dữ liệu.
A6: KB2 | B6: RANH GIỚI DỮ LIỆU | C6: Hai phụ huynh có con HỌC CÙNG MỘT LỚP | D6: Đăng nhập vai PHỤ HUYNH. Mở “Báo cáo”. ĐẾM số học sinh được nhắc tới và ghi TÊN em đó. | E6: Đăng nhập vai PHỤ HUYNH. Mở “Báo cáo”. ĐẾM số học sinh được nhắc tới và ghi TÊN em đó. | F6: Đăng nhập vai QUẢN TRỊ VIÊN. Mở “Danh sách” lớp 7B1. ĐẾM tổng số học sinh trong lớp. | G6: Người 1 và Người 2 mỗi người phải đếm được ĐÚNG 1 học sinh, và hai cái tên đó phải KHÁC NHAU. Người 3 đếm được nhiều hơn (cả lớp). Con của hai người này học cùng lớp 7B1 — đây chính là phép thử khó nhất. | H6: Nếu một phụ huynh thấy từ 2 học sinh trở lên, hoặc thấy tên con của người kia — DỪNG ĐỢT THỬ và báo ngay.
A7: KB3 | B7: CHUYỀN TAY | C7: Điểm danh của giáo viên hiện lên bảng của ban giám hiệu | D7: Đăng nhập vai GIÁO VIÊN CHỦ NHIỆM 7B1. Mở “Điểm danh”, đánh dấu đủ cả lớp rồi bấm “Lưu điểm danh”. Báo cho hai người kia biết là đã lưu xong. | E7: TRƯỚC khi Người 1 lưu: mở “Cơ sở”, ghi lại con số ở cột “Điểm danh hôm nay” của lớp 7B1. SAU khi Người 1 báo xong: tải lại trang và ghi con số mới. | F7: Đăng nhập vai GIÁO VIÊN CHỦ NHIỆM 6A2. Trước và sau khi Người 1 lưu, mở “Danh sách” lớp mình và ghi lại tình hình lớp 6A2. | G7: Con số của Người 2 phải TĂNG sau khi Người 1 lưu. Lớp 6A2 của Người 3 phải KHÔNG đổi gì cả. | H7: Nếu số của Người 2 không đổi: có thể app không cập nhật, hoặc phải tải lại trang mới thấy — ghi rõ bạn có phải tải lại không.
A8: KB4 | B8: CHUYỀN TAY | C8: Học sinh tổ trưởng điểm danh thay giáo viên | D8: Đăng nhập vai HỌC SINH (tổ trưởng). Mở “Điểm danh”, đánh dấu vài bạn rồi lưu. Sau đó đăng xuất, đăng nhập lại vai GIÁO VIÊN CHỦ NHIỆM và mở “Điểm danh” xem có thấy kết quả em vừa ghi không. | E8: Đăng nhập vai HỌC SINH THƯỜNG (cùng lớp 7B1). Nhìn thanh menu và ghi lại các mục bạn thấy. | F8: Đăng nhập vai QUẢN TRỊ VIÊN. Mở “Điểm danh” lớp 7B1 và ghi lại tình trạng hiện tại. | G8: Giáo viên (Người 1) phải thấy đúng kết quả mà em tổ trưởng vừa ghi. Học sinh thường (Người 2) TUYỆT ĐỐI không có mục “Điểm danh” trên menu. Quản trị viên (Người 3) thấy giống giáo viên. | H8: Nếu học sinh thường thấy mục “Điểm danh” — báo ngay, quyền đang bị mở rộng hơn dự tính.
A9: KB5 | B9: CHUYỀN TAY | C9: Việc giáo viên giao hiện lên máy học sinh | D9: Đăng nhập vai GIÁO VIÊN CHỦ NHIỆM 7B1. Mở “WIG”, tạo một WIG tuần mới và thêm một việc cần làm (lead measure) với tên dễ nhận ra, ví dụ “ĐỌC SÁCH TEST”. Báo cho hai người kia. | E9: Đăng nhập vai HỌC SINH lớp 7B1. Mở “Bảng điểm của tôi”, tìm xem có việc “ĐỌC SÁCH TEST” không. Nếu có thì tick thử. | F9: Đăng nhập vai HỌC SINH lớp 6A2. Mở “Bảng điểm của tôi”, tìm xem có việc “ĐỌC SÁCH TEST” không. | G9: Học sinh lớp 7B1 (Người 2) PHẢI thấy việc mới. Học sinh lớp 6A2 (Người 3) TUYỆT ĐỐI KHÔNG được thấy — vì đó là lớp khác, cơ sở khác. | H9: Nếu học sinh lớp 6A2 thấy việc của lớp 7B1 — DỪNG ĐỢT THỬ và báo ngay.
A10: KB6 | B10: CÙNG LÚC | C10: Hai người cùng sửa một mục tiêu | D10: Đăng nhập vai GIÁO VIÊN CHỦ NHIỆM 7B1. Mở “WIG”, bấm sửa một WIG. Đổi ô “Đến (mục tiêu)” thành 100. KHOAN bấm lưu — đếm 1-2-3 cùng Người 3 rồi cả hai bấm lưu một lúc. | E10: Quan sát và bấm giờ. Ghi lại: ai bấm trước, cách nhau bao lâu. | F10: Đăng nhập vai QUẢN TRỊ VIÊN. Mở đúng WIG đó của lớp 7B1, đổi ô “Đến (mục tiêu)” thành 200. Cùng đếm 1-2-3 với Người 1 rồi bấm lưu. | G10: Sau khi cả hai lưu xong, cả ba cùng tải lại trang. Con số cuối cùng phải GIỐNG NHAU trên cả ba máy — không được máy này 100 máy kia 200. Ghi lại con số cuối là bao nhiêu. | H10: Ghi rõ: app có báo gì cho người bị ghi đè không, hay lặng lẽ lấy người bấm sau? Bạn thấy cách xử lý đó chấp nhận được chưa?
A11: KB7 | B11: CÙNG LÚC | C11: Hai người cùng điểm danh một lớp | D11: Đăng nhập vai GIÁO VIÊN CHỦ NHIỆM 7B1. Mở “Điểm danh”. Đánh dấu em đầu danh sách là “Vắng”. Cùng đếm 1-2-3 với Người 3 rồi bấm lưu. | E11: Quan sát cả hai màn hình và ghi lại chuyện gì xảy ra. | F11: Đăng nhập vai QUẢN TRỊ VIÊN. Mở “Điểm danh” lớp 7B1. Đánh dấu CHÍNH EM ĐÓ là “Có mặt”. Cùng đếm 1-2-3 rồi bấm lưu. | G11: Sau khi cả hai lưu, cùng tải lại trang. Trạng thái của em đó phải giống nhau trên cả hai máy. | H11: Đây là tình huống có thật: giáo viên và tổ trưởng cùng điểm danh một lúc. Ghi rõ app xử lý thế nào.
A12: KB8 | B12: HỎI Ý TRƯỜNG | C12: Phân quyền hiện tại có đúng ý trường chưa? | D12: Đọc và trả lời phần bên phải theo góc nhìn giáo viên. | E12: Đọc và trả lời phần bên phải theo góc nhìn ban giám hiệu. | F12: Đọc và trả lời phần bên phải theo góc nhìn quản trị viên. | G12: Đây KHÔNG phải phép thử đúng-sai mà là câu hỏi cho trường quyết định. Cả ba cùng bàn rồi mỗi người ghi ý mình: (1) Ban giám hiệu hiện KHÔNG có mục Điểm danh, WIG và Họp WIG — có đúng ý trường không? (2) Ban giám hiệu KHÔNG sửa được điểm danh, chỉ xem. Đúng chưa? (3) Học sinh tổ trưởng ghi được điểm danh CẢ LỚP (chỉ trong ngày hôm nay). Trường có thấy an tâm không? (4) Phụ huynh chỉ xem, không nhắn lại được cho giáo viên. Có cần thêm đường phản hồi không? (5) Giáo viên chủ nhiệm sửa được điểm danh lùi 6 ngày. Con số 6 ngày có hợp lý không? | H12: Không có đáp án đúng. Ghi thật ý của mình.

Sheet SỔ LỖI
A1: SỔ LỖI — theo dõi xuyên suốt mọi vòng thử
A2: Mỗi lỗi ghi MỘT dòng, giữ nguyên dòng đó qua các vòng và cập nhật cột Trạng thái cho tới khi xong.
A4: Mã lỗi | B4: Vòng phát hiện | C4: Ai báo | D4: Màn hình nào | E4: Chuyện gì xảy ra | F4: Nặng hay nhẹ | G4: Bạn mong nó phải thế nào | H4: Trạng thái | I4: Vòng đã kiểm lại | J4: Ghi chú của người sửa
A5: L01
A6: L02
A7: L03
A8: L04
A9: L05
A10: L06
A11: L07
A12: L08
A13: L09
A14: L10
A15: L11
A16: L12
... A44: L40

Sheet TỔNG HỢP
A1: TỔNG HỢP — tự tính từ ba sheet người thử
A2: Không phải điền gì ở đây. Số tự cập nhật khi ba người điền phiếu.
A4: VÒNG THỬ 1
A5: Người thử | B5: Đúng như mô tả | C5: Gần đúng, khác một chút | D5: Khác hẳn mô tả | E5: Không làm được / bị kẹt | F5: Chưa thử | G5: Điểm TB | H5: Số chặng ⚠
A6: N1 · Giáo viên | B6: =COUNTIF('N1 · Giáo viên'!$D$11:$D$43,DS!$A$2) | C6: =COUNTIF('N1 · Giáo viên'!$D$11:$D$43,DS!$A$3) | D6: =COUNTIF('N1 · Giáo viên'!$D$11:$D$43,DS!$A$4) | E6: =COUNTIF('N1 · Giáo viên'!$D$11:$D$43,DS!$A$5) | F6: =COUNTIF('N1 · Giáo viên'!$D$11:$D$43,DS!$A$6) | G6: =IFERROR(ROUND(AVERAGE('N1 · Giáo viên'!$E$11:$E$43),1),"—") | H6: =COUNTIF('N1 · Giáo viên'!$O$11:$O$43,"⚠")
A7: N2 · Ban giám hiệu | B7: =COUNTIF('N2 · Ban giám hiệu'!$D$11:$D$37,DS!$A$2) | C7: =COUNTIF('N2 · Ban giám hiệu'!$D$11:$D$37,DS!$A$3) | D7: =COUNTIF('N2 · Ban giám hiệu'!$D$11:$D$37,DS!$A$4) | E7: =COUNTIF('N2 · Ban giám hiệu'!$D$11:$D$37,DS!$A$5) | F7: =COUNTIF('N2 · Ban giám hiệu'!$D$11:$D$37,DS!$A$6) | G7: =IFERROR(ROUND(AVERAGE('N2 · Ban giám hiệu'!$E$11:$E$37),1),"—") | H7: =COUNTIF('N2 · Ban giám hiệu'!$O$11:$O$37,"⚠")
A8: N3 · Quản trị viên | B8: =COUNTIF('N3 · Quản trị viên'!$D$11:$D$36,DS!$A$2) | C8: =COUNTIF('N3 · Quản trị viên'!$D$11:$D$36,DS!$A$3) | D8: =COUNTIF('N3 · Quản trị viên'!$D$11:$D$36,DS!$A$4) | E8: =COUNTIF('N3 · Quản trị viên'!$D$11:$D$36,DS!$A$5) | F8: =COUNTIF('N3 · Quản trị viên'!$D$11:$D$36,DS!$A$6) | G8: =IFERROR(ROUND(AVERAGE('N3 · Quản trị viên'!$E$11:$E$36),1),"—") | H8: =COUNTIF('N3 · Quản trị viên'!$O$11:$O$36,"⚠")
A10: VÒNG THỬ 2
A11: Người thử | B11: Đúng như mô tả | C11: Gần đúng, khác một chút | D11: Khác hẳn mô tả | E11: Không làm được / bị kẹt | F11: Chưa thử | G11: Điểm TB | H11: Số chặng ⚠
A12: N1 · Giáo viên | B12: =COUNTIF('N1 · Giáo viên'!$H$11:$H$43,DS!$A$2) | C12: =COUNTIF('N1 · Giáo viên'!$H$11:$H$43,DS!$A$3) | D12: =COUNTIF('N1 · Giáo viên'!$H$11:$H$43,DS!$A$4) | E12: =COUNTIF('N1 · Giáo viên'!$H$11:$H$43,DS!$A$5) | F12: =COUNTIF('N1 · Giáo viên'!$H$11:$H$43,DS!$A$6) | G12: =IFERROR(ROUND(AVERAGE('N1 · Giáo viên'!$I$11:$I$43),1),"—") | H12: =COUNTIF('N1 · Giáo viên'!$O$11:$O$43,"⚠")
A13: N2 · Ban giám hiệu | B13: =COUNTIF('N2 · Ban giám hiệu'!$H$11:$H$37,DS!$A$2) | C13: =COUNTIF('N2 · Ban giám hiệu'!$H$11:$H$37,DS!$A$3) | D13: =COUNTIF('N2 · Ban giám hiệu'!$H$11:$H$37,DS!$A$4) | E13: =COUNTIF('N2 · Ban giám hiệu'!$H$11:$H$37,DS!$A$5) | F13: =COUNTIF('N2 · Ban giám hiệu'!$H$11:$H$37,DS!$A$6) | G13: =IFERROR(ROUND(AVERAGE('N2 · Ban giám hiệu'!$I$11:$I$37),1),"—") | H13: =COUNTIF('N2 · Ban giám hiệu'!$O$11:$O$37,"⚠")
A14: N3 · Quản trị viên | B14: =COUNTIF('N3 · Quản trị viên'!$H$11:$H$36,DS!$A$2) | C14: =COUNTIF('N3 · Quản trị viên'!$H$11:$H$36,DS!$A$3) | D14: =COUNTIF('N3 · Quản trị viên'!$H$11:$H$36,DS!$A$4) | E14: =COUNTIF('N3 · Quản trị viên'!$H$11:$H$36,DS!$A$5) | F14: =COUNTIF('N3 · Quản trị viên'!$H$11:$H$36,DS!$A$6) | G14: =IFERROR(ROUND(AVERAGE('N3 · Quản trị viên'!$I$11:$I$36),1),"—") | H14: =COUNTIF('N3 · Quản trị viên'!$O$11:$O$36,"⚠")
A16: VÒNG THỬ 3
A17: Người thử | B17: Đúng như mô tả | C17: Gần đúng, khác một chút | D17: Khác hẳn mô tả | E17: Không làm được / bị kẹt | F17: Chưa thử | G17: Điểm TB | H17: Số chặng ⚠
A18: N1 · Giáo viên | B18: =COUNTIF('N1 · Giáo viên'!$L$11:$L$43,DS!$A$2) | C18: =COUNTIF('N1 · Giáo viên'!$L$11:$L$43,DS!$A$3) | D18: =COUNTIF('N1 · Giáo viên'!$L$11:$L$43,DS!$A$4) | E18: =COUNTIF('N1 · Giáo viên'!$L$11:$L$43,DS!$A$5) | F18: =COUNTIF('N1 · Giáo viên'!$L$11:$L$43,DS!$A$6) | G18: =IFERROR(ROUND(AVERAGE('N1 · Giáo viên'!$M$11:$M$43),1),"—") | H18: =COUNTIF('N1 · Giáo viên'!$O$11:$O$43,"⚠")
A19: N2 · Ban giám hiệu | B19: =COUNTIF('N2 · Ban giám hiệu'!$L$11:$L$37,DS!$A$2) | C19: =COUNTIF('N2 · Ban giám hiệu'!$L$11:$L$37,DS!$A$3) | D19: =COUNTIF('N2 · Ban giám hiệu'!$L$11:$L$37,DS!$A$4) | E19: =COUNTIF('N2 · Ban giám hiệu'!$L$11:$L$37,DS!$A$5) | F19: =COUNTIF('N2 · Ban giám hiệu'!$L$11:$L$37,DS!$A$6) | G19: =IFERROR(ROUND(AVERAGE('N2 · Ban giám hiệu'!$M$11:$M$37),1),"—") | H19: =COUNTIF('N2 · Ban giám hiệu'!$O$11:$O$37,"⚠")
A20: N3 · Quản trị viên | B20: =COUNTIF('N3 · Quản trị viên'!$L$11:$L$36,DS!$A$2) | C20: =COUNTIF('N3 · Quản trị viên'!$L$11:$L$36,DS!$A$3) | D20: =COUNTIF('N3 · Quản trị viên'!$L$11:$L$36,DS!$A$4) | E20: =COUNTIF('N3 · Quản trị viên'!$L$11:$L$36,DS!$A$5) | F20: =COUNTIF('N3 · Quản trị viên'!$L$11:$L$36,DS!$A$6) | G20: =IFERROR(ROUND(AVERAGE('N3 · Quản trị viên'!$M$11:$M$36),1),"—") | H20: =COUNTIF('N3 · Quản trị viên'!$O$11:$O$36,"⚠")
A22: KỊCH BẢN PHỐI HỢP
A23: Đúng như mô tả | B23: =COUNTIF('PHỐI HỢP'!$I$5:$I$12,DS!$A$2)
A24: Gần đúng, khác một chút | B24: =COUNTIF('PHỐI HỢP'!$I$5:$I$12,DS!$A$3)
A25: Khác hẳn mô tả | B25: =COUNTIF('PHỐI HỢP'!$I$5:$I$12,DS!$A$4)
A26: Không làm được / bị kẹt | B26: =COUNTIF('PHỐI HỢP'!$I$5:$I$12,DS!$A$5)
A27: Chưa thử | B27: =COUNTIF('PHỐI HỢP'!$I$5:$I$12,DS!$A$6)
A29: SỔ LỖI
A30: Mới ghi nhận | B30: =COUNTIF('SỔ LỖI'!$H$5:$H$44,DS!$E$2)
A31: Đang sửa | B31: =COUNTIF('SỔ LỖI'!$H$5:$H$44,DS!$E$3)
A32: Đã sửa — chờ kiểm lại | B32: =COUNTIF('SỔ LỖI'!$H$5:$H$44,DS!$E$4)
A33: Đã kiểm lại — xong | B33: =COUNTIF('SỔ LỖI'!$H$5:$H$44,DS!$E$5)
A34: Không sửa (có lý do) | B34: =COUNTIF('SỔ LỖI'!$H$5:$H$44,DS!$E$6)
A35: Tổng số lỗi đã ghi | B35: =COUNTA('SỔ LỖI'!$E$5:$E$44)
A37: CÁCH TÌM CHẶNG CÓ VẤN ĐỀ: mở sheet của từng người, bấm lọc ở cột ⚠ (cột cuối cùng) và chọn hiện những dòng có dấu ⚠. Đó là các chặng có người báo app khác mô tả hoặc bị kẹt.
